[2025-08-03T00:30:24.162+0000] {taskinstance.py:1157} INFO - Dependencies all met for dep_context=non-requeueable deps ti=<TaskInstance: nyc_taxi_iceberg_etl.get_latest_date scheduled__2025-08-02T18:25:20.574593+00:00 [queued]>
[2025-08-03T00:30:24.172+0000] {taskinstance.py:1157} INFO - Dependencies all met for dep_context=requeueable deps ti=<TaskInstance: nyc_taxi_iceberg_etl.get_latest_date scheduled__2025-08-02T18:25:20.574593+00:00 [queued]>
[2025-08-03T00:30:24.173+0000] {taskinstance.py:1359} INFO - Starting attempt 2 of 2
[2025-08-03T00:30:24.251+0000] {taskinstance.py:1380} INFO - Executing <Task(PythonOperator): get_latest_date> on 2025-08-02 18:25:20.574593+00:00
[2025-08-03T00:30:24.257+0000] {standard_task_runner.py:57} INFO - Started process 383 to run task
[2025-08-03T00:30:24.260+0000] {standard_task_runner.py:84} INFO - Running: ['***', 'tasks', 'run', 'nyc_taxi_iceberg_etl', 'get_latest_date', 'scheduled__2025-08-02T18:25:20.574593+00:00', '--job-id', '15', '--raw', '--subdir', 'DAGS_FOLDER/nyc_taxi_iceberg_etl.py', '--cfg-path', '/tmp/tmph4arompb']
[2025-08-03T00:30:24.262+0000] {standard_task_runner.py:85} INFO - Job 15: Subtask get_latest_date
[2025-08-03T00:30:24.324+0000] {task_command.py:415} INFO - Running <TaskInstance: nyc_taxi_iceberg_etl.get_latest_date scheduled__2025-08-02T18:25:20.574593+00:00 [running]> on host 114f606b1815
[2025-08-03T00:30:24.398+0000] {taskinstance.py:1660} INFO - Exporting env vars: AIRFLOW_CTX_DAG_OWNER='data-engineering' AIRFLOW_CTX_DAG_ID='nyc_taxi_iceberg_etl' AIRFLOW_CTX_TASK_ID='get_latest_date' AIRFLOW_CTX_EXECUTION_DATE='2025-08-02T18:25:20.574593+00:00' AIRFLOW_CTX_TRY_NUMBER='2' AIRFLOW_CTX_DAG_RUN_ID='scheduled__2025-08-02T18:25:20.574593+00:00'
[2025-08-03T00:30:24.421+0000] {taskinstance.py:1935} ERROR - Task failed with exception
Traceback (most recent call last):
  File "/home/airflow/.local/lib/python3.8/site-packages/airflow/operators/python.py", line 192, in execute
    return_value = self.execute_callable()
  File "/home/airflow/.local/lib/python3.8/site-packages/airflow/operators/python.py", line 209, in execute_callable
    return self.python_callable(*self.op_args, **self.op_kwargs)
  File "/opt/airflow/dags/nyc_taxi_iceberg_etl.py", line 58, in get_latest_processed_date
    pg_hook.run(create_table_sql)
  File "/home/airflow/.local/lib/python3.8/site-packages/airflow/providers/common/sql/hooks/sql.py", line 385, in run
    with closing(self.get_conn()) as conn:
  File "/home/airflow/.local/lib/python3.8/site-packages/airflow/providers/postgres/hooks/postgres.py", line 125, in get_conn
    conn = deepcopy(self.connection or self.get_connection(conn_id))
  File "/home/airflow/.local/lib/python3.8/site-packages/airflow/hooks/base.py", line 72, in get_connection
    conn = Connection.get_connection_from_secrets(conn_id)
  File "/home/airflow/.local/lib/python3.8/site-packages/airflow/models/connection.py", line 477, in get_connection_from_secrets
    raise AirflowNotFoundException(f"The conn_id `{conn_id}` isn't defined")
airflow.exceptions.AirflowNotFoundException: The conn_id `postgres_default` isn't defined
[2025-08-03T00:30:24.426+0000] {taskinstance.py:1398} INFO - Marking task as FAILED. dag_id=nyc_taxi_iceberg_etl, task_id=get_latest_date, execution_date=20250802T182520, start_date=20250803T003024, end_date=20250803T003024
[2025-08-03T00:30:24.433+0000] {standard_task_runner.py:104} ERROR - Failed to execute job 15 for task get_latest_date (The conn_id `postgres_default` isn't defined; 383)
[2025-08-03T00:30:24.442+0000] {local_task_job_runner.py:228} INFO - Task exited with return code 1
[2025-08-03T00:30:24.458+0000] {taskinstance.py:2776} INFO - 0 downstream tasks scheduled from follow-on schedule check
