[2025-08-03T00:25:22.992+0000] {taskinstance.py:1157} INFO - Dependencies all met for dep_context=non-requeueable deps ti=<TaskInstance: nyc_taxi_iceberg_etl.get_latest_date scheduled__2025-08-02T18:25:20.574593+00:00 [queued]>
[2025-08-03T00:25:22.995+0000] {taskinstance.py:1157} INFO - Dependencies all met for dep_context=requeueable deps ti=<TaskInstance: nyc_taxi_iceberg_etl.get_latest_date scheduled__2025-08-02T18:25:20.574593+00:00 [queued]>
[2025-08-03T00:25:22.995+0000] {taskinstance.py:1359} INFO - Starting attempt 1 of 2
[2025-08-03T00:25:23.055+0000] {taskinstance.py:1380} INFO - Executing <Task(PythonOperator): get_latest_date> on 2025-08-02 18:25:20.574593+00:00
[2025-08-03T00:25:23.057+0000] {standard_task_runner.py:57} INFO - Started process 961 to run task
[2025-08-03T00:25:23.059+0000] {standard_task_runner.py:84} INFO - Running: ['***', 'tasks', 'run', 'nyc_taxi_iceberg_etl', 'get_latest_date', 'scheduled__2025-08-02T18:25:20.574593+00:00', '--job-id', '7', '--raw', '--subdir', 'DAGS_FOLDER/nyc_taxi_iceberg_etl.py', '--cfg-path', '/tmp/tmpgqo9iq2p']
[2025-08-03T00:25:23.060+0000] {standard_task_runner.py:85} INFO - Job 7: Subtask get_latest_date
[2025-08-03T00:25:23.089+0000] {task_command.py:415} INFO - Running <TaskInstance: nyc_taxi_iceberg_etl.get_latest_date scheduled__2025-08-02T18:25:20.574593+00:00 [running]> on host 6fb539098074
[2025-08-03T00:25:23.128+0000] {taskinstance.py:1660} INFO - Exporting env vars: AIRFLOW_CTX_DAG_OWNER='data-engineering' AIRFLOW_CTX_DAG_ID='nyc_taxi_iceberg_etl' AIRFLOW_CTX_TASK_ID='get_latest_date' AIRFLOW_CTX_EXECUTION_DATE='2025-08-02T18:25:20.574593+00:00' AIRFLOW_CTX_TRY_NUMBER='1' AIRFLOW_CTX_DAG_RUN_ID='scheduled__2025-08-02T18:25:20.574593+00:00'
[2025-08-03T00:25:23.138+0000] {taskinstance.py:1935} ERROR - Task failed with exception
Traceback (most recent call last):
  File "/home/airflow/.local/lib/python3.8/site-packages/airflow/operators/python.py", line 192, in execute
    return_value = self.execute_callable()
  File "/home/airflow/.local/lib/python3.8/site-packages/airflow/operators/python.py", line 209, in execute_callable
    return self.python_callable(*self.op_args, **self.op_kwargs)
  File "/opt/airflow/dags/nyc_taxi_iceberg_etl.py", line 58, in get_latest_processed_date
    pg_hook.run(create_table_sql)
  File "/home/airflow/.local/lib/python3.8/site-packages/airflow/providers/common/sql/hooks/sql.py", line 385, in run
    with closing(self.get_conn()) as conn:
  File "/home/airflow/.local/lib/python3.8/site-packages/airflow/providers/postgres/hooks/postgres.py", line 125, in get_conn
    conn = deepcopy(self.connection or self.get_connection(conn_id))
  File "/home/airflow/.local/lib/python3.8/site-packages/airflow/hooks/base.py", line 72, in get_connection
    conn = Connection.get_connection_from_secrets(conn_id)
  File "/home/airflow/.local/lib/python3.8/site-packages/airflow/models/connection.py", line 477, in get_connection_from_secrets
    raise AirflowNotFoundException(f"The conn_id `{conn_id}` isn't defined")
airflow.exceptions.AirflowNotFoundException: The conn_id `postgres_default` isn't defined
[2025-08-03T00:25:23.142+0000] {taskinstance.py:1398} INFO - Marking task as UP_FOR_RETRY. dag_id=nyc_taxi_iceberg_etl, task_id=get_latest_date, execution_date=20250802T182520, start_date=20250803T002522, end_date=20250803T002523
[2025-08-03T00:25:23.147+0000] {standard_task_runner.py:104} ERROR - Failed to execute job 7 for task get_latest_date (The conn_id `postgres_default` isn't defined; 961)
[2025-08-03T00:25:23.158+0000] {local_task_job_runner.py:228} INFO - Task exited with return code 1
[2025-08-03T00:25:23.170+0000] {taskinstance.py:2776} INFO - 0 downstream tasks scheduled from follow-on schedule check
